<?xml version="1.0"?>
<robot name="wheel" xmlns:xacro="http://www.ros.org/wiki/xacro">
  
  <!-- Wheels -->
  <property name="wheel_radius" value="0.07" /> 
  <property name="wheel_height" value="0.05" />
  <property name="wheel_mass" value="1.2" /> <!-- in kg-->
  

  
  <macro name="cylinder_inertia" params="m r h">
    <inertia  ixx="${m*(3*r*r+h*h)/12}" ixy = "0" ixz = "0"
              iyy="${m*(3*r*r+h*h)/12}" iyz = "0"
              izz="${m*r*r/2}" /> 
  </macro>
  
  <xacro:macro name="wheel" params="fb lr parent translateX translateY flipY"> <!--fb : front, back ; lr: left, right -->
    <link name="${fb}_${lr}_wheel">
      <visual>
        <origin xyz="0 0 0" rpy="${flipY*M_PI/2} 0  0 " /> 
        <geometry>
          <mesh filename="package://agv_description/meshes/roue.stl"/>
        </geometry>
        <material name="DarkGray" />
      </visual>
      <collision>
        <origin xyz="0 0 0" rpy="${flipY*M_PI/2} 0 0 " />
        <geometry>
          <mesh filename="package://agv_description/meshes/roue.stl"/>
        </geometry>
      </collision>
      <inertial>
        <mass value="${wheel_mass}" />
        <origin xyz="0 0 0" />
        <!--<cylinder_inertia  m="${wheel_mass}" r="${wheel_radius}" h="${wheel_height}" />-->
        <inertia ixx="0.01" ixy="0.0" ixz="0"
         iyx="0.0" iyy="0.01" iyz="0.0" 
         izx="0" izy="0.0" izz="0.02" />
      </inertial>
    </link>

    <gazebo reference="${fb}_${lr}_wheel">
      <mu1 value="0.1"/>
      <mu2 value="0.1"/>
      <kp  value="500000.0" />
      <kd  value="10.0" />
      <fdir1 value="1 0 0"/>
      <material>Gazebo/Grey</material>
    </gazebo>

    <joint name="${fb}_${lr}_wheel_joint" type="continuous">
      <parent link="${parent}"/>
      <child link="${fb}_${lr}_wheel"/>
      <origin xyz="${translateX * base_x_origin_to_wheel_origin} ${translateY * base_y_origin_to_wheel_origin} ${base_z_origin_to_wheel_origin}" rpy="0 0 0" /> 
      <axis xyz="0 1 0" rpy="0  0" />
      <limit effort="100" velocity="100"/>
      <joint_properties damping="0.0" friction="0.0"/>
    </joint>

    <!-- Transmission is important to link the joints and the controller -->
    <transmission name="${fb}_${lr}_wheel_joint_trans">
      <type>transmission_interface/SimpleTransmission</type>
      <joint name="${fb}_${lr}_wheel_joint">
      <hardwareInterface>hardware_interface/VelocityJointInterface</hardwareInterface>
    </joint>
      <actuator name="${fb}_${lr}_wheel_joint_motor">
        <hardwareInterface>hardware_interface/VelocityJointInterface</hardwareInterface>
        <mechanicalReduction>1</mechanicalReduction>
      </actuator>
    </transmission>
   
  </xacro:macro>
</robot>